Workbook

Sheet Instructions
A1: Perform the following in the dataset from the 'Dataset' sheet.
B3: 1) Handling Missing Values:
C4: • Check for missing values in the 'Price' column. How would you handle products with missing price information?
C5: • If there are products with missing categories, propose a strategy to impute or deal with these missing values effectively.
B7: 2) Correcting Inconsistent Data:
C8: • Identify any inconsistent text formats present in the "Product Name" column.
C9: • Identify any typos present in the "Category" column.
C10: • Use the find and replace function to standardize the text formats in the "Product Name" column and fix any typos or misspellings in the "Category" column.
B12: 3) Removing Duplicates:
C13: • Identify any duplicate rows within the dataset based on the entirety of each row, and remove them if any.
B15: 4) Splitting and Merging Data:
C16: • Split the "Product ID" column into two separate columns for " Manufacturing Date" and "Country Code". Remove unnecessary characters, if any.
C17: • Merge the "Brand Name" and "Product Name" columns into one column named "Product Brand".
B19: 5) Number Formatting:
C20: • Format the data type of the "Price" column to currency format.
C21: • Format the "Manufacturing Date" column to display dates in the "DD-MM-YYYY " format.
B23: 6) Conditional Formatting:
C24: • Apply data bar or color scales conditional formatting in the "Price" column.
C25: • Create a custom rule for conditional formatting in the "Category" column to highlight cells where the category is "Electronics."

Sheet Dataset
A1: Product ID | B1: Product Name | C1: Brand Name | D1: Price ($) | E1: Quantity | F1: Category
A2: 28-JAN-US | B2: laptop | C2: Dell | D2: 1000 | E2: 30 | F2: Electronics | H2: 1.Handling Missing Values | Q2: 1. Missing Category | U2: =UPPER(K3) | V2: 2. Correcting Inconsistent Data | AD2: 5. . Nmber Formatting
A3: 15-FEB-US | B3: Sneakers | C3: Nike | D3: 80 | E3: 15 | F3: Fashion
A4: 03-MAR-US | B4: Coffee Maker | C4: Keurig | D4: 130 | E4: 40 | F4: Kitchen
A5: 11-APR-US | B5: smartphone | C5: Samsung | D5: 900 | E5: 25 | F5: Electronics | R5: Category | S5: Missing Category | V5: Product Name | X5: Typos Category | Z5: Product Name | AA5: Category | AC5: Price | AD5: Currency | AG5: Manufacturing Date | AH5: Manufacturing Date2
A6: 22-MAY-US | B6: Backpack | C6: North Face | D6: 70 | E6: 20 | K6: Price ($) | L6: Missing Price($) | R6: Electronics | S6: =IF(R6="","Unknown",R6) -> Electronics | V6: laptop | X6: Electronics | Z6: =PROPER(TRIM(V6)) -> Laptop | AA6: Electronics | AC6: 1000 | AD6: 1000 | AG6: 45685 | AH6: =TEXT(Dataset!AG6,"DD-MM-YYYY") -> 28-01-2025
A7: 07-JUN-UK | B7: Headphones | C7: Sony | E7: 45 | F7: Electroni | K7: 1000 | L7: =IF(ISBLANK(K7),ROUND(AVERAGEIF($F$2:$F$32,F2,$K$7:$K$37),0),K7) -> 1000 | R7: Fashion | S7: =IF(R7="","Unknown",R7) -> Fashion | V7: Sneakers | X7: Fashion | Z7: =PROPER(TRIM(V7)) -> Sneakers | AA7: Fashion | AC7: 80 | AD7: 80 | AG7: 45703 | AH7: =TEXT(Dataset!AG7,"DD-MM-YYYY") -> 15-02-2025
A8: 19-JUL-UK | B8: T-shirt | C8: Adidas | D8: 30 | E8: 5 | F8: Fashion | K8: 80 | L8: =IF(ISBLANK(K8),ROUND(AVERAGEIF($F$2:$F$32,F3,$K$7:$K$37),0),K8) -> 80 | R8: Kitchen | S8: =IF(R8="","Unknown",R8) -> Kitchen | V8: Coffee Maker | X8: Kitchen | Z8: =PROPER(TRIM(V8)) -> Coffee Maker | AA8: Kitchen | AC8: 130 | AD8: 130 | AG8: 45719 | AH8: =TEXT(Dataset!AG8,"DD-MM-YYYY") -> 03-03-2025
A9: 23-AUG-UK | B9: Blender | C9: Ninja | D9: 90 | E9: 35 | F9: Kitchen | K9: 130 | L9: =IF(ISBLANK(K9),ROUND(AVERAGEIF($F$2:$F$32,F4,$K$7:$K$37),0),K9) -> 130 | R9: Electronics | S9: =IF(R9="","Unknown",R9) -> Electronics | V9: smartphone | X9: Electronics | Z9: =PROPER(TRIM(V9)) -> Smartphone | AA9: Electronics | AC9: 900 | AD9: 900 | AG9: 45758 | AH9: =TEXT(Dataset!AG9,"DD-MM-YYYY") -> 11-04-2025
A10: 05-SEP-UK | B10: Tablet | C10: Apple | D10: 500 | E10: 50 | F10: Electronics | K10: 900 | L10: =IF(ISBLANK(K10),ROUND(AVERAGEIF($F$2:$F$32,F5,$K$7:$K$37),0),K10) -> 900 | S10: =IF(R10="","Unknown",R10) -> Unknown | V10: Backpack | X10: Unknown | Z10: =PROPER(TRIM(V10)) -> Backpack | AA10: Unknown | AC10: 70 | AD10: 70 | AG10: 45799 | AH10: =TEXT(Dataset!AG10,"DD-MM-YYYY") -> 22-05-2025
A11: 14-OCT-UK | B11: Hiking Boots | C11: Timberland | D11: 130 | E11: 10 | F11: Outdoor | K11: 70 | L11: =IF(ISBLANK(K11),ROUND(AVERAGEIF($F$2:$F$32,F6,$K$7:$K$37),0),K11) -> 70 | N11: Blank Count : | O11: =COUNTBLANK(D2:D32) -> 3 | R11: Electroni | S11: =IF(R11="","Unknown",R11) -> Electroni | V11: Headphones | X11: Electroni | Z11: =PROPER(TRIM(V11)) -> Headphones | AA11: Electronics | AC11: 187 | AD11: 187 | AG11: 45815 | AH11: =TEXT(Dataset!AG11,"DD-MM-YYYY") -> 07-06-2025
A12: 17-JUN-IN | B12: Laptop | C12: HP | D12: 950 | E12: 25 | F12: Electronics | L12: =IF(ISBLANK(K12),ROUND(AVERAGEIF($F$2:$F$32,F7,$K$7:$K$37),0),K12) -> 187 | R12: Fashion | S12: =IF(R12="","Unknown",R12) -> Fashion | V12: T-shirt | X12: Fashion | Z12: =PROPER(TRIM(V12)) -> T-Shirt | AA12: Fashion | AC12: 30 | AD12: 30 | AG12: 45857 | AH12: =TEXT(Dataset!AG12,"DD-MM-YYYY") -> 19-07-2025
A13: 25-NOV-AU | B13: Sneakers | C13: Adidas | D13: 90 | E13: 40 | K13: 30 | L13: =IF(ISBLANK(K13),ROUND(AVERAGEIF($F$2:$F$32,F8,$K$7:$K$37),0),K13) -> 30 | R13: Kitchen | S13: =IF(R13="","Unknown",R13) -> Kitchen | V13: Blender | X13: Kitchen | Z13: =PROPER(TRIM(V13)) -> Blender | AA13: Kitchen | AC13: 90 | AD13: 90 | AG13: 45892 | AH13: =TEXT(Dataset!AG13,"DD-MM-YYYY") -> 23-08-2025
A14: 08-DEC-DE | B14: Coffee Maker | C14: Nespresso | D14: 120 | E14: 35 | K14: 90 | L14: =IF(ISBLANK(K14),ROUND(AVERAGEIF($F$2:$F$32,F9,$K$7:$K$37),0),K14) -> 90 | R14: Electronics | S14: =IF(R14="","Unknown",R14) -> Electronics | V14: Tablet | X14: Electronics | Z14: =PROPER(TRIM(V14)) -> Tablet | AA14: Electronics | AC14: 500 | AD14: 500 | AG14: 45905 | AH14: =TEXT(Dataset!AG14,"DD-MM-YYYY") -> 05-09-2025
A15: 18-FEB-CA | B15: Smartwatch | C15: Fitbit | D15: 150 | E15: 15 | F15: Electroni | K15: 500 | L15: =IF(ISBLANK(K15),ROUND(AVERAGEIF($F$2:$F$32,F10,$K$7:$K$37),0),K15) -> 500 | R15: Outdoor | S15: =IF(R15="","Unknown",R15) -> Outdoor | V15: Hiking Boots | X15: Outdoor | Z15: =PROPER(TRIM(V15)) -> Hiking Boots | AA15: Outdoor | AC15: 130 | AD15: 130 | AG15: 45944 | AH15: =TEXT(Dataset!AG15,"DD-MM-YYYY") -> 14-10-2025
A16: 16-APR-ES | B16: headphones | C16: Bose | D16: 250 | E16: 20 | F16: Electroni | K16: 130 | L16: =IF(ISBLANK(K16),ROUND(AVERAGEIF($F$2:$F$32,F11,$K$7:$K$37),0),K16) -> 130 | R16: Electronics | S16: =IF(R16="","Unknown",R16) -> Electronics | V16: Laptop | X16: Electronics | Z16: =PROPER(TRIM(V16)) -> Laptop | AA16: Electronics | AC16: 950 | AD16: 950 | AG16: 45825 | AH16: =TEXT(Dataset!AG16,"DD-MM-YYYY") -> 17-06-2025
A17: 21-AUG-CA | B17: Laptop Bag | C17: Samsonite | D17: 50 | E17: 35 | F17: Accessories | K17: 950 | L17: =IF(ISBLANK(K17),ROUND(AVERAGEIF($F$2:$F$32,F12,$K$7:$K$37),0),K17) -> 950 | S17: =IF(R17="","Unknown",R17) -> Unknown | V17: Sneakers | X17: Unknown | Z17: =PROPER(TRIM(V17)) -> Sneakers | AA17: Unknown | AC17: 90 | AD17: 90 | AG17: 45986 | AH17: =TEXT(Dataset!AG17,"DD-MM-YYYY") -> 25-11-2025
A18: 20-AUG-CN | B18: Smartwatch | C18: Huawei | D18: 160 | E18: 15 | F18: Electroni | K18: 90 | L18: =IF(ISBLANK(K18),ROUND(AVERAGEIF($F$2:$F$32,F13,$K$7:$K$37),0),K18) -> 90 | S18: =IF(R18="","Unknown",R18) -> Unknown | V18: Coffee Maker | X18: Unknown | Z18: =PROPER(TRIM(V18)) -> Coffee Maker | AA18: Unknown | AC18: 120 | AD18: 120 | AG18: 45999 | AH18: =TEXT(Dataset!AG18,"DD-MM-YYYY") -> 08-12-2025
A19: 27-JAN-IT | B19: laptop | C19: Asus | D19: 980 | E19: 10 | F19: Electronics | K19: 120 | L19: =IF(ISBLANK(K19),ROUND(AVERAGEIF($F$2:$F$32,F14,$K$7:$K$37),0),K19) -> 120 | R19: Electroni | S19: =IF(R19="","Unknown",R19) -> Electroni | V19: Smartwatch | X19: Electroni | Z19: =PROPER(TRIM(V19)) -> Smartwatch | AA19: Electronics | AC19: 150 | AD19: 150 | AG19: 45706 | AH19: =TEXT(Dataset!AG19,"DD-MM-YYYY") -> 18-02-2025
A20: 01-MAR-UK | B20: Sunglasses | C20: Oakley | D20: 150 | E20: 15 | F20: Fashion | K20: 150 | L20: =IF(ISBLANK(K20),ROUND(AVERAGEIF($F$2:$F$32,F15,$K$7:$K$37),0),K20) -> 150 | R20: Electroni | S20: =IF(R20="","Unknown",R20) -> Electroni | V20: headphones | X20: Electroni | Z20: =PROPER(TRIM(V20)) -> Headphones | AA20: Electronics | AC20: 250 | AD20: 250 | AG20: 45763 | AH20: =TEXT(Dataset!AG20,"DD-MM-YYYY") -> 16-04-2025
A21: 14-AUG-US | B21: Camping Tent | C21: Coleman | E21: 10 | F21: Outdoor | K21: 250 | L21: =IF(ISBLANK(K21),ROUND(AVERAGEIF($F$2:$F$32,F16,$K$7:$K$37),0),K21) -> 250 | R21: Accessories | S21: =IF(R21="","Unknown",R21) -> Accessories | V21: Laptop Bag | X21: Accessories | Z21: =PROPER(TRIM(V21)) -> Laptop Bag | AA21: Accessories | AC21: 50 | AD21: 50 | AG21: 45890 | AH21: =TEXT(Dataset!AG21,"DD-MM-YYYY") -> 21-08-2025
A22: 14-MAY-RU | B22: Camera | C22: Nikon | D22: 700 | E22: 50 | F22: Electronics | K22: 50 | L22: =IF(ISBLANK(K22),ROUND(AVERAGEIF($F$2:$F$32,F17,$K$7:$K$37),0),K22) -> 50 | R22: Electroni | S22: =IF(R22="","Unknown",R22) -> Electroni | V22: Smartwatch | X22: Electroni | Z22: =PROPER(TRIM(V22)) -> Smartwatch | AA22: Electronics | AC22: 160 | AD22: 160 | AG22: 45889 | AH22: =TEXT(Dataset!AG22,"DD-MM-YYYY") -> 20-08-2025
A23: 09-JAN-CA | B23: Microwave | C23: Panasonic | D23: 80 | E23: 20 | F23: Kitchen | K23: 160 | L23: =IF(ISBLANK(K23),ROUND(AVERAGEIF($F$2:$F$32,F18,$K$7:$K$37),0),K23) -> 160 | R23: Electronics | S23: =IF(R23="","Unknown",R23) -> Electronics | V23: laptop | X23: Electronics | Z23: =PROPER(TRIM(V23)) -> Laptop | AA23: Electronics | AC23: 980 | AD23: 980 | AG23: 45684 | AH23: =TEXT(Dataset!AG23,"DD-MM-YYYY") -> 27-01-2025
A24: 19-JUL-BR | B24: Fitness Tracker | C24: Xiaomi | D24: 150 | E24: 30 | K24: 980 | L24: =IF(ISBLANK(K24),ROUND(AVERAGEIF($F$2:$F$32,F19,$K$7:$K$37),0),K24) -> 980 | R24: Fashion | S24: =IF(R24="","Unknown",R24) -> Fashion | V24: Sunglasses | X24: Fashion | Z24: =PROPER(TRIM(V24)) -> Sunglasses | AA24: Fashion | AC24: 150 | AD24: 150 | AG24: 45717 | AH24: =TEXT(Dataset!AG24,"DD-MM-YYYY") -> 01-03-2025
A25: 29-SEP-CA | B25: Smartphone | C25: Google | D25: 800 | E25: 45 | F25: Electronics | K25: 150 | L25: =IF(ISBLANK(K25),ROUND(AVERAGEIF($F$2:$F$32,F20,$K$7:$K$37),0),K25) -> 150 | R25: Outdoor | S25: =IF(R25="","Unknown",R25) -> Outdoor | V25: Camping Tent | X25: Outdoor | Z25: =PROPER(TRIM(V25)) -> Camping Tent | AA25: Outdoor | AC25: 130 | AD25: 130 | AG25: 45883 | AH25: =TEXT(Dataset!AG25,"DD-MM-YYYY") -> 14-08-2025
A26: 03-JUN-CA | B26: Sunglasses | C26: Ray-Ban | E26: 25 | F26: Fashion | L26: =IF(ISBLANK(K26),ROUND(AVERAGEIF($F$2:$F$32,F21,$K$7:$K$37),0),K26) -> 130 | R26: Electronics | S26: =IF(R26="","Unknown",R26) -> Electronics | V26: Camera | X26: Electronics | Z26: =PROPER(TRIM(V26)) -> Camera | AA26: Electronics | AC26: 700 | AD26: 700 | AG26: 45791 | AH26: =TEXT(Dataset!AG26,"DD-MM-YYYY") -> 14-05-2025
A27: 11-JUL-CA | B27: Blender | C27: Vitamix | D27: 400 | E27: 40 | F27: Kitchen | K27: 700 | L27: =IF(ISBLANK(K27),ROUND(AVERAGEIF($F$2:$F$32,F22,$K$7:$K$37),0),K27) -> 700 | R27: Kitchen | S27: =IF(R27="","Unknown",R27) -> Kitchen | V27: Microwave | X27: Kitchen | Z27: =PROPER(TRIM(V27)) -> Microwave | AA27: Kitchen | AC27: 80 | AD27: 80 | AG27: 45666 | AH27: =TEXT(Dataset!AG27,"DD-MM-YYYY") -> 09-01-2025
A28: 07-MAR-CA | B28: Dress | C28: Zara | D28: 60 | E28: 30 | F28: Fashion | K28: 80 | L28: =IF(ISBLANK(K28),ROUND(AVERAGEIF($F$2:$F$32,F23,$K$7:$K$37),0),K28) -> 80 | S28: =IF(R28="","Unknown",R28) -> Unknown | V28: Fitness Tracker | X28: Unknown | Z28: =PROPER(TRIM(V28)) -> Fitness Tracker | AA28: Unknown | AC28: 150 | AD28: 150 | AG28: 45857 | AH28: =TEXT(Dataset!AG28,"DD-MM-YYYY") -> 19-07-2025
A29: 13-APR-CA | B29: Toaster | C29: Hamilton | D29: 40 | E29: 10 | F29: Kitchen | K29: 150 | L29: =IF(ISBLANK(K29),ROUND(AVERAGEIF($F$2:$F$32,F24,$K$7:$K$37),0),K29) -> 150 | R29: Electronics | S29: =IF(R29="","Unknown",R29) -> Electronics | V29: Smartphone | X29: Electronics | Z29: =PROPER(TRIM(V29)) -> Smartphone | AA29: Electronics | AC29: 800 | AD29: 800 | AG29: 45929 | AH29: =TEXT(Dataset!AG29,"DD-MM-YYYY") -> 29-09-2025
A30: 24-MAY-CA | B30: Fitness Tracker | C30: Garmin | D30: 130 | E30: 5 | F30: Electronics | K30: 800 | L30: =IF(ISBLANK(K30),ROUND(AVERAGEIF($F$2:$F$32,F25,$K$7:$K$37),0),K30) -> 800 | R30: Fashion | S30: =IF(R30="","Unknown",R30) -> Fashion | V30: Sunglasses | X30: Fashion | Z30: =PROPER(TRIM(V30)) -> Sunglasses | AA30: Fashion | AC30: 74 | AD30: 74 | AG30: 45811 | AH30: =TEXT(Dataset!AG30,"DD-MM-YYYY") -> 03-06-2025
A31: 02-DEC-CA | B31: Jeans | C31: Levi's | D31: 50 | E31: 50 | F31: Fashion | L31: =IF(ISBLANK(K31),ROUND(AVERAGEIF($F$2:$F$32,F26,$K$7:$K$37),0),K31) -> 74 | R31: Kitchen | S31: =IF(R31="","Unknown",R31) -> Kitchen | V31: Blender | X31: Kitchen | Z31: =PROPER(TRIM(V31)) -> Blender | AA31: Kitchen | AC31: 400 | AD31: 400 | AG31: 45849 | AH31: =TEXT(Dataset!AG31,"DD-MM-YYYY") -> 11-07-2025
A32: 09-JUL-FR | B32: Watch | C32: Casio | D32: 100 | E32: 20 | F32: Accessories | K32: 400 | L32: =IF(ISBLANK(K32),ROUND(AVERAGEIF($F$2:$F$32,F27,$K$7:$K$37),0),K32) -> 400 | R32: Fashion | S32: =IF(R32="","Unknown",R32) -> Fashion | V32: Dress | X32: Fashion | Z32: =PROPER(TRIM(V32)) -> Dress | AA32: Fashion | AC32: 60 | AD32: 60 | AG32: 45723 | AH32: =TEXT(Dataset!AG32,"DD-MM-YYYY") -> 07-03-2025
K33: 60 | L33: =IF(ISBLANK(K33),ROUND(AVERAGEIF($F$2:$F$32,F28,$K$7:$K$37),0),K33) -> 60 | R33: Kitchen | S33: =IF(R33="","Unknown",R33) -> Kitchen | V33: Toaster | X33: Kitchen | Z33: =PROPER(TRIM(V33)) -> Toaster | AA33: Kitchen | AC33: 40 | AD33: 40 | AG33: 45760 | AH33: =TEXT(Dataset!AG33,"DD-MM-YYYY") -> 13-04-2025
K34: 40 | L34: =IF(ISBLANK(K34),ROUND(AVERAGEIF($F$2:$F$32,F29,$K$7:$K$37),0),K34) -> 40 | R34: Electronics | S34: =IF(R34="","Unknown",R34) -> Electronics | V34: Fitness Tracker | X34: Electronics | Z34: =PROPER(TRIM(V34)) -> Fitness Tracker | AA34: Electronics | AC34: 130 | AD34: 130 | AG34: 45801 | AH34: =TEXT(Dataset!AG34,"DD-MM-YYYY") -> 24-05-2025
K35: 130 | L35: =IF(ISBLANK(K35),ROUND(AVERAGEIF($F$2:$F$32,F30,$K$7:$K$37),0),K35) -> 130 | R35: Fashion | S35: =IF(R35="","Unknown",R35) -> Fashion | V35: Jeans | X35: Fashion | Z35: =PROPER(TRIM(V35)) -> Jeans | AA35: Fashion | AC35: 50 | AD35: 50 | AG35: 45993 | AH35: =TEXT(Dataset!AG35,"DD-MM-YYYY") -> 02-12-2025
K36: 50 | L36: =IF(ISBLANK(K36),ROUND(AVERAGEIF($F$2:$F$32,F31,$K$7:$K$37),0),K36) -> 50 | R36: Accessories | S36: =IF(R36="","Unknown",R36) -> Accessories | V36: Watch | X36: Accessories | Z36: =PROPER(TRIM(V36)) -> Watch | AA36: Accessories | AC36: 100 | AD36: 100 | AG36: 45847 | AH36: =TEXT(Dataset!AG36,"DD-MM-YYYY") -> 09-07-2025
K37: 100 | L37: =IF(ISBLANK(K37),ROUND(AVERAGEIF($F$2:$F$32,F32,$K$7:$K$37),0),K37) -> 100
K40: 3. Duplicates | Y40: 4.Splitting | AF40: 6.Conditional Formatting
I43: Product ID | J43: Product Name | K43: Brand Name | L43: Price ($) | M43: Quantity | N43: Category | Q43: Product ID | R43: Product Name | S43: Brand Name | T43: Price($) | U43: Quantity | V43: Category | X43: Product ID | Y43: Manufacturing Date | Z43: Country Code | AB43: Product Name | AC43: Brand Name | AD43: Product Brand
I44: 28-JAN-US | J44: laptop | K44: Dell | L44: 1000 | M44: 30 | N44: Electronics | Q44: 28-JAN-US | R44: Laptop | S44: Dell | T44: 1000 | U44: 30 | V44: Electronics | X44: 28-JAN-US | Y44: 45685 | Z44: US | AB44: Laptop | AC44: Dell | AD44: =CONCATENATE(AB44," - ",AC44) -> Laptop - Dell | AH44: Price($) | AK44: Category
...
